<?xml version="1.0"?>

<robot xmlns:xacro="http://ros.org/wiki/xacro">
    <xacro:include filename="$(find mini_pupper_description)/xacro/const.xacro" />
    <xacro:macro name="leg" params="name front_sign side_sign">
            
        <!--
        ********************************************
        ******              PARTS             ******
        ********************************************
        -->
        <link name="${name}-pod">
            <visual>
                <geometry>
                    <mesh filename="package://mini_pupper_description/meshes/${name}1.stl" scale="1.0 1.0 1.0"/>
                </geometry>
                <origin rpy="0.0 ${right_angle} 0.0" xyz="0.0 0.0 0.0"/>
                <material name="black"/>
            </visual>
            <collision>
                <geometry>
                    <box size="0.031 0.030 0.038"/>
                </geometry>
                <origin rpy="0.0 0.0 0.0" xyz="0.006 0.0 -0.006"/>
            </collision>
        </link>
        
        <link name="${name}-femur">
            <visual>
                <geometry>
                    <mesh filename="package://mini_pupper_description/meshes/${name}2.stl" scale="1.0 1.0 1.0"/>
                </geometry>
                <origin rpy="${right_angle} 0.0 -${right_angle}" xyz="0.0 0.0 0.0"/>
                <material name="dark_grey"/>          
            </visual>
            <collision>
                <geometry>
                    <box size="0.054 0.007 0.002"/>
                </geometry>
		<origin rpy="0.0 0.0 0.0" xyz="${femur_offset_x} 0.0 0.0"/>
            </collision>
        </link>
        
        <link name="${name}-tibia">
            <visual>
                <geometry>
                    <mesh filename="package://mini_pupper_description/meshes/${name}3.stl" scale="1.0 1.0 1.0"/>
                </geometry>
                <origin rpy="${right_angle} 0.0 -${right_angle}" xyz="0.0 0 0"/>
                <material name="grey"/>  
            </visual>
            <collision>
                <geometry>
                    <box size="0.060 0.006 0.002"/>
                </geometry>
		<origin rpy="0.0 0.0 0.0" xyz="${tibia_offset_x} 0 0"/>
            </collision>
        </link>
    
        <link name="${name}-foot">
            <visual>
                <geometry>
                    <mesh filename="package://mini_pupper_description/meshes/${name}foot.stl" scale="1.0 1.0 1.0"/>
                </geometry>
                <origin rpy="${right_angle} 0.0 -${right_angle}" xyz="0.0 0 0"/>
                <material name="grey"/>  
            </visual>
            <collision>
                <geometry>
                    <box size="0.060 0.006 0.002"/>
                </geometry>
                <origin rpy="0.0 0.0 0.0" xyz="0.030 0 0"/>
            </collision>
        </link>
    
        <!--
        ********************************************
        ******             JOINTS             ******
        ********************************************
        -->
        <joint name="${name}-abd" type="revolute">
            <parent link="base_link"/>
            <child link="${name}-pod"/>
	    <origin rpy="0 -${right_angle} 0" xyz="${front_sign}${abd_offset_x} ${side_sign}${abd_offset_y} 0"/>
            <axis xyz="0 0 1"/>
            <limit lower="-0.4" upper="0.4" effort="100" velocity="1000"/>      
        </joint>
        
        <joint name="${name}-hips" type="revolute">
            <parent link="${name}-pod"/>
            <child link="${name}-femur"/>
	    <origin rpy="-${right_angle} -${angle_135} 0.0" xyz="0.0 ${side_sign}${hip_offset_y} 0.0"/>
            <axis xyz="0 0 1"/>
            <limit lower="-${angle_45}" upper="${angle_45}" effort="100" velocity="1000"/>      
        </joint>
        
        <joint name="${name}-knee" type="revolute">
            <parent link="${name}-femur"/>
            <child link="${name}-tibia"/>
	    <origin rpy="0.0 0.0 -${right_angle}" xyz="${knee_offset_x} 0.0 ${side_sign}${knee_offset_z}"/>
            <axis xyz="0 0 1"/>
            <limit lower="-${angle_45}" upper="${angle_45}" effort="100" velocity="1000"/>      
        </joint>
        
        <joint name="${name}-foot" type="fixed">
            <parent link="${name}-tibia"/>
            <child link="${name}-foot"/>
            <origin rpy="0.0 0.0 0.0" xyz="${foot_offset_x} 0 0"/>
            <axis xyz="0 0 1"/>
        </joint>
    </xacro:macro>
</robot>
